Workbook

Sheet Hoja6
B1: Preguntas | C1: Respuestas
A2: Tecsa | B2: =COUNTIFS('Tabla General'!$F:$F,"<>",'Tabla General'!$C:$C,Hoja6!A2) -> 140 | C2: =COUNTIFS('Tabla General'!$H:$H,"<>",'Tabla General'!$C:$C,Hoja6!A2) -> 140
A3: Propamat | B3: =COUNTIFS('Tabla General'!$F:$F,"<>",'Tabla General'!$C:$C,Hoja6!A3) -> 50 | C3: =COUNTIFS('Tabla General'!$H:$H,"<>",'Tabla General'!$C:$C,Hoja6!A3) -> 50
A4: Fleischmann S. A. | B4: =COUNTIFS('Tabla General'!$F:$F,"<>",'Tabla General'!$C:$C,Hoja6!A4) -> 117 | C4: =COUNTIFS('Tabla General'!$H:$H,"<>",'Tabla General'!$C:$C,Hoja6!A4) -> 117
A5: Global Data | B5: =COUNTIFS('Tabla General'!$F:$F,"<>",'Tabla General'!$C:$C,Hoja6!A5) -> 142 | C5: =COUNTIFS('Tabla General'!$H:$H,"<>",'Tabla General'!$C:$C,Hoja6!A5) -> 142
A6: CS Energy | B6: =COUNTIFS('Tabla General'!$F:$F,"<>",'Tabla General'!$C:$C,Hoja6!A6) -> 29 | C6: =COUNTIFS('Tabla General'!$H:$H,"<>",'Tabla General'!$C:$C,Hoja6!A6) -> 29
B7: =SUM(B2:B6) -> 478 | C7: =SUM(C2:C6) -> 478
A9: GENERAL/ADM | B9: =COUNTIFS('Tabla General'!F:F,"<>",'Tabla General'!E:E,Hoja6!A9) -> 58 | C9: =COUNTIFS('Tabla General'!J:J,"Respondido",'Tabla General'!E:E,Hoja6!A9) -> 58
A10: OOCC | B10: =COUNTIFS('Tabla General'!F:F,"<>",'Tabla General'!E:E,Hoja6!A10) -> 64 | C10: =COUNTIFS('Tabla General'!J:J,"Respondido",'Tabla General'!E:E,Hoja6!A10) -> 64
A11: BMS | B11: =COUNTIFS('Tabla General'!F:F,"<>",'Tabla General'!E:E,Hoja6!A11) -> 26 | C11: =COUNTIFS('Tabla General'!J:J,"Respondido",'Tabla General'!E:E,Hoja6!A11) -> 26
A12: SEGURIDAD | B12: =COUNTIFS('Tabla General'!F:F,"<>",'Tabla General'!E:E,Hoja6!A12) -> 19 | C12: =COUNTIFS('Tabla General'!J:J,"Respondido",'Tabla General'!E:E,Hoja6!A12) -> 19
A13: TELECOM | B13: =COUNTIFS('Tabla General'!F:F,"<>",'Tabla General'!E:E,Hoja6!A13) -> 111 | C13: =COUNTIFS('Tabla General'!J:J,"Respondido",'Tabla General'!E:E,Hoja6!A13) -> 111
A14: ELECTRICO | B14: =COUNTIFS('Tabla General'!F:F,"<>",'Tabla General'!E:E,Hoja6!A14) -> 96 | C14: =COUNTIFS('Tabla General'!J:J,"Respondido",'Tabla General'!E:E,Hoja6!A14) -> 96
A15: HVAC | B15: =COUNTIFS('Tabla General'!F:F,"<>",'Tabla General'!E:E,Hoja6!A15) -> 60 | C15: =COUNTIFS('Tabla General'!J:J,"Respondido",'Tabla General'!E:E,Hoja6!A15) -> 60
A16: PCI | B16: =COUNTIFS('Tabla General'!F:F,"<>",'Tabla General'!E:E,Hoja6!A16) -> 6 | C16: =COUNTIFS('Tabla General'!J:J,"Respondido",'Tabla General'!E:E,Hoja6!A16) -> 6
A17: IIFF | B17: =COUNTIFS('Tabla General'!F:F,"<>",'Tabla General'!E:E,Hoja6!A17) -> 19 | C17: =COUNTIFS('Tabla General'!J:J,"Respondido",'Tabla General'!E:E,Hoja6!A17) -> 19
A18: EHS | B18: =COUNTIFS('Tabla General'!F:F,"<>",'Tabla General'!E:E,Hoja6!A18) -> 4 | C18: =COUNTIFS('Tabla General'!J:J,"Respondido",'Tabla General'!E:E,Hoja6!A18) -> 4
A19: COMISIONAMIENTO | B19: =COUNTIFS('Tabla General'!F:F,"<>",'Tabla General'!E:E,Hoja6!A19) -> 5 | C19: =COUNTIFS('Tabla General'!J:J,"Respondido",'Tabla General'!E:E,Hoja6!A19) -> 5
A20: DETECCION | B20: =COUNTIFS('Tabla General'!F:F,"<>",'Tabla General'!E:E,Hoja6!A20) -> 10 | C20: =COUNTIFS('Tabla General'!J:J,"Respondido",'Tabla General'!E:E,Hoja6!A20) -> 10
B21: =SUM(B9:B20) -> 478 | C21: =SUM(C9:C20) -> 478

Sheet Tabla General
A1: Sitio: Odata ST01 EX05
A2: Proyecto: RFP ODATA -DC ST01 EX05
A4: n° | B4: n° interno | C4: GC | D4: Tipo de Consulta | E4: Especialidad | F4: Pregunta | G4: Documento relacionado | H4: Respuesta | I4: Observación | J4: Respondido | K4: Columna1
A5: 460 | B5: 43 | C5: Fleischmann S. A. | E5: SEGURIDAD | F5: indicar que software o plataforma es la existente para sistema de CCTV y Control de Acceso | H5: Avigilion. | J5: =IF(Tabla1[[#This Row],[Respuesta]]="","Sin respuesta","Respondido") -> Respondido | K5: Validar con Oscar Lopez
A6: 357 | B6: 105 | C6: Tecsa | E6: BMS | F6: BMS: Confirmar que la licencia requerida para la plataforma Ignition es la versión Pro | H6: Ignition, considerar licencia para Gateway principal y otra para Gateway de respaldo. | J6: =IF(Tabla1[[#This Row],[Respuesta]]="","Sin respuesta","Respondido") -> Respondido | K6: Preguntar a Oscar Lopez de Odata
A7: 274 | B7: 22 | C7: Tecsa | E7: BMS | F7: SEGURIDAD ELECTRONICA: Favor mencionar modelo, marca, y versión del BMS actual. | H7: Securtity expert. | J7: =IF(Tabla1[[#This Row],[Respuesta]]="","Sin respuesta","Respondido") -> Respondido | K7: Preguntar a Oscar Lopez de Odata
A8: 478 | B8: 61 | C8: Fleischmann S. A. | E8: HVAC | F8: Por favor indicar caída de presión para poder cotizar equipos fan-coils. | G8: =#VALUE! -> #VALUE! | H8: No considerar fancoils. | J8: =IF(Tabla1[[#This Row],[Respuesta]]="","Sin respuesta","Respondido") -> Respondido
A9: 477 | B9: 60 | C9: Fleischmann S. A. | E9: HVAC | F9: Por favor aclarar porque la ficha de equipos fancoils esta dentro de una carpeta que dice anulados. | G9: ODA-0004-CLI-HD-009 | H9: No considerar fancoils. | J9: =IF(Tabla1[[#This Row],[Respuesta]]="","Sin respuesta","Respondido") -> Respondido
A10: 476 | B10: 59 | C10: Fleischmann S. A. | E10: HVAC | F10: Confirmar que los equipos CRAC son suministrados por Odata, ya que en pagina 23 de EE.TT. No se menciona. Sin embargo se entrega documento ODA-0004-CLI-RFQ-005 que confunde porque es el mismo documento para equipos: Chillers, deltacube, crah que son suministrados por Odata. Por favor aclarar | G10: RFP INSTALCIONES EX05_REV2, página 23 | H10: Ver respuesta 83. | J10: =IF(Tabla1[[#This Row],[Respuesta]]="","Sin respuesta","Respondido") -> Respondido
A11: 475 | B11: 58 | C11: Fleischmann S. A. | E11: HVAC | F11: Por favor indicar cuanto peso por m2 resiste la viga para poder calcular el soporte de cañerías y el soporte considerado puede perforar la viga? | G11: =#VALUE! -> #VALUE! | H11: Ver Respuesta 448. | J11: =IF(Tabla1[[#This Row],[Respuesta]]="","Sin respuesta","Respondido") -> Respondido
A12: 474 | B12: 57 | C12: Fleischmann S. A. | E12: HVAC | F12: Confirmar norma ASME B31.3 para soldadura por lo tanto no se requiere tintas penetrantes ni ensayos radiográficos | G12: ODA-0004-CLI-ET-009 | H12: Ver respuesta 473. | J12: =IF(Tabla1[[#This Row],[Respuesta]]="","Sin respuesta","Respondido") -> Respondido
A13: 473 | B13: 56 | C13: Fleischmann S. A. | E13: HVAC | F13: Por favor confirmar que podemos trabajar bajo norma ASME B31.3 y no bajo norma AWSD 1.1 solicitada en documento. La norma solicitada se utiliza en el diseños de estructuras y no aplica para la especialidad de climatización que trabaja a baja presiones. | G13: ODA-0004-CLI-ET-009 | H13: Confirmamos que, para el alcance de climatización, corresponde la aplicación de la norma ASME B31.3 (Process Piping) . No obstante, en relación con los soportes de tuberías y equipos, estos constituyen elementos de carácter estructural secundario, por lo que las soldaduras asociadas se encuentran reguladas por la norma AWS D1.1 – Structural Welding Code – Steel. En ambos casos el Proponente deberá presentar los dossier de Calidad de los suministros con sus respectivos ensayos, siendo obligatoria en todo caso la inspección certificada de las soldaduras. | J13: =IF(Tabla1[[#This Row],[Respuesta]]="","Sin respuesta","Respondido") -> Respondido
A14: 472 | B14: 55 | C14: Fleischmann S. A. | E14: HVAC | F14: Indicar si la cantidad de equipos CRAC-FCU-BMS corresponden a 2 o 3 unidades (Planos figuran 2, fichas figuran 3 unidades) | G14: ODA-0004-CLI-PL-003 | H14: Existen de ambas configuraciones. | J14: =IF(Tabla1[[#This Row],[Respuesta]]="","Sin respuesta","Respondido") -> Respondido
A15: 471 | B15: 54 | C15: Fleischmann S. A. | E15: TELECOM | F15: Se solicita confirmar la necesidad de demoler el tramo de banco de ductos señalado en el plano ODA-0004-TEL-PL-0004, tomando en cuenta que los pavimentos de hormigón en dicho sector están terminados. | G15: ODA-0004-TEL-PL-0004 | H15: No, las partidas de ese plano ya están ejecutadas | J15: =IF(Tabla1[[#This Row],[Respuesta]]="","Sin respuesta","Respondido") -> Respondido
A16: 470 | B16: 53 | C16: Fleischmann S. A. | E16: OOCC | F16: Se solicita entregar el plano de estructura de la parrilla nivel +497,4, indicado en listado de planos (ODA-0004-EST-PL-020). Se requiere para evaluar apropiadamente los soportes de las instalaciones y cielos falsos que deben colgarse de la misma | G16: ODA-0004-ARQ-PL-097 | H16: Se adjunta. | J16: =IF(Tabla1[[#This Row],[Respuesta]]="","Sin respuesta","Respondido") -> Respondido
A17: 469 | B17: 52 | C17: Fleischmann S. A. | E17: OOCC | F17: De acuerdo a lo señalado en el punto 5.10.2 de las EE.TT. Los revestimientos en ambas caras deben recubrir todos los elementos estructurales dejando una superficie lisa desde el NPT hasta el cielo o remate de encuentro superior. Se solicita confirmar que no se requieren pinturas sobre el nivel de cielo falso. | G17: ODA-0004-ARQ-ET-001 | H17: Si, se confirma solo para los recintos que tienen cielo falsos. | J17: =IF(Tabla1[[#This Row],[Respuesta]]="","Sin respuesta","Respondido") -> Respondido
A18: 468 | B18: 51 | C18: Fleischmann S. A. | E18: OOCC | F18: Se solicita confirmar que los refuerzos en tabiques y ventanas se encuentran ejecutados, y que sólo se requiere verificar las medidas antes de mandar a fabricar. En caso contrario se requiere que nos entreguen los planos de estructuras correspondientes | G18: ODA-0004-ARQ-ET-001 | H18: Ver respuesta 51. | J18: =IF(Tabla1[[#This Row],[Respuesta]]="","Sin respuesta","Respondido") -> Respondido
A19: 467 | B19: 50 | C19: Fleischmann S. A. | E19: OOCC | F19: Se solicita confirmar que los refuerzos en tabiques y ventanas se encuentran ejecutados, y que sólo se requiere verificar las medidas antes de mandar a fabricar. En caso contrario se requiere que nos entreguen los planos de estructuras correspondientes | G19: ODA-0004-ARQ-ET-001 | H19: Ver respuesta 51. | J19: =IF(Tabla1[[#This Row],[Respuesta]]="","Sin respuesta","Respondido") -> Respondido
A20: 466 | B20: 49 | C20: Fleischmann S. A. | E20: OOCC | F20: Se solicita confirmar que todas las estructuras que requieren protección al fuego mediante pintura intumescente ya están pintadas, incluyendo las escaleras de escape. De no ser así, se requiere la entrega de los planos de cálculo para hacer estudio de masividades y poder estimar los espesores requeridos de acuerdo a lo señalado en el punto 6.7.3 de las EE.TT., o que se entreguen los esquemas de pintura a utilizar. | G20: ODA-0004-ARQ-ET-001 | H20: No es alcance de este RFP la estructura principal y pintura intumescente. | J20: =IF(Tabla1[[#This Row],[Respuesta]]="","Sin respuesta","Respondido") -> Respondido
A21: 465 | B21: 48 | C21: Fleischmann S. A. | E21: TELECOM | F21: Confirmar que el 100% de racks y PDU serán parte del suministro ODATA. ( Rack Principal y Rack de acceso) | H21: Odata proveerá los racks del proyecto, estos serán entregados sobre camión en obra. El proponente deberá realizar su desplazamiento horizontal y vertical hasta su punto de instalación, realizando los respectivos anclajes del mismo e instalando todos los dispositivos asociados al mismo. | J21: =IF(Tabla1[[#This Row],[Respuesta]]="","Sin respuesta","Respondido") -> Respondido
A22: 464 | B22: 47 | C22: Fleischmann S. A. | E22: TELECOM | F22: Confirmar que los equipos Access Point serán parte del suministro ODATA | H22: Si, se confirma. | J22: =IF(Tabla1[[#This Row],[Respuesta]]="","Sin respuesta","Respondido") -> Respondido
A23: 463 | B23: 46 | C23: Fleischmann S. A. | E23: TELECOM | F23: Se deberá considerar en esta etapa canalizaciones Fiber Runner. | H23: No forma parte del alcance de este RFP | J23: =IF(Tabla1[[#This Row],[Respuesta]]="","Sin respuesta","Respondido") -> Respondido
A24: 462 | B24: 45 | C24: Fleischmann S. A. | E24: DETECCION | F24: Se deberá considerar Estación de Monitoreo (Onyxworks) para sistema de detección de incendio o este es existente en etapa anterior | H24: Si, se debe considerar una Estacion de Monitoreo. | J24: =IF(Tabla1[[#This Row],[Respuesta]]="","Sin respuesta","Respondido") -> Respondido
A25: 461 | B25: 44 | C25: Fleischmann S. A. | E25: SEGURIDAD | F25: Para la ejecución de sistemas de Seguridad Electrónica se deberán considerar subcontrato aprobados por Odata, o podremos utilizar mano de obra calificada y certificada propia del proponente. | H25: Pueden utilizar mano de obra calificada y certificada por el Proponente | J25: =IF(Tabla1[[#This Row],[Respuesta]]="","Sin respuesta","Respondido") -> Respondido
A26: 459 | B26: 42 | C26: Fleischmann S. A. | E26: SEGURIDAD | F26: Favor confirmar marca y modelos de Cámaras de sistema Video Vigilancia | H26: Cámaras marca Pelco | J26: =IF(Tabla1[[#This Row],[Respuesta]]="","Sin respuesta","Respondido") -> Respondido
A27: 458 | B27: 41 | C27: Fleischmann S. A. | E27: IIFF | F27: Según lo indicado en el RFP INSTALCIONES EX05_REV2 se solicita indica en ANEXO XIII no indica el uso del edificio que se muestra en planta entre zona 2 Y ZONA 6. Esta zona estará disponible para su uso? | G27: 5.1.1 ORGANIZACIÓN DE LA INSTALACIÓN DE FAENA, Anexo XIII_Esquema Instalación de Faenas | H27: Ver Respuesta 457 | J27: =IF(Tabla1[[#This Row],[Respuesta]]="","Sin respuesta","Respondido") -> Respondido
A28: 457 | B28: 40 | C28: Fleischmann S. A. | E28: IIFF | F28: Según lo indicado en el RFP INSTALCIONES EX05_REV2 se solicita indica en ANEXO XIII posibles ubicaciones para futuros contenedores. Se solicita indicar si las zonas junto a los estacionamientos, donde se ven materiales al suelo , estará despejada y disponible para uso. | G28: 5.1.1 ORGANIZACIÓN DE LA INSTALACIÓN DE FAENA, Anexo XIII_Esquema Instalación de Faenas | H28: Si, se confirma lo indicado. No obstante, el PROPONENTE deberá presentar un Plan de Movilización e Instalaciones de Faena para su revisión y aprobación por parte de ODATA, como requisito previo al inicio de los trabajos. | J28: =IF(Tabla1[[#This Row],[Respuesta]]="","Sin respuesta","Respondido") -> Respondido
A29: 456 | B29: 39 | C29: Fleischmann S. A. | E29: IIFF | F29: Según lo indicado en el RFP INSTALCIONES EX05_REV2 se solicita indica si la bodega Odata N° 3 del ANEXO XIII estará disponible para uso del proponente. | G29: 5.1.1 ORGANIZACIÓN DE LA INSTALACIÓN DE FAENA, Anexo XIII_Esquema Instalación de Faenas | H29: No, es uso exclusivo de Odata | J29: =IF(Tabla1[[#This Row],[Respuesta]]="","Sin respuesta","Respondido") -> Respondido
A30: 455 | B30: 38 | C30: Fleischmann S. A. | E30: IIFF | F30: Según lo indicado en el RFP INSTALCIONES EX05_REV2 se solicita indica capacidad para comedor, no indicado en el ANEXO XIII | G30: 5.1.1 ORGANIZACIÓN DE LA INSTALACIÓN DE FAENA, Anexo XIII_Esquema Instalación de Faenas | H30: Son 6 módulos con capacidad para 30 personas cada uno. | J30: =IF(Tabla1[[#This Row],[Respuesta]]="","Sin respuesta","Respondido") -> Respondido
A31: 454 | B31: 37 | C31: Fleischmann S. A. | E31: IIFF | F31: Según lo indicado en el RFP INSTALCIONES EX05_REV2 Se solicita indica la capacidad eléctrica del instalación de faena actual y disponibilidad de potencia para conexión de futuros contenedores. | G31: 5.1.1 ORGANIZACIÓN DE LA INSTALACIÓN DE FAENA | H31: Empalme de 300 kVA | J31: =IF(Tabla1[[#This Row],[Respuesta]]="","Sin respuesta","Respondido") -> Respondido
A32: 453 | B32: 36 | C32: Fleischmann S. A. | E32: GENERAL/ADM | F32: En base a la respuesta N°55 Se solicita indicar el alcance del permiso de edificación actual si tienen incluidas las obras de este contrato y solo se debe modificar el constructor, favor compartir el permiso actual de construcción. | H32: Existe permiso de edificación para la ejecución de las obras de este contrato. | J32: =IF(Tabla1[[#This Row],[Respuesta]]="","Sin respuesta","Respondido") -> Respondido
A33: 452 | B33: 35 | C33: Fleischmann S. A. | E33: GENERAL/ADM | F33: Según lo indicado en el RFP INSTALCIONES EX05_REV2 se solicita indicar si los TAG de los equipos suministrados por el cliente, son del alcance del proveedor. | G33: 4.6 TAG – Identificación de los equipos | H33: Son alcance del proveedor | J33: =IF(Tabla1[[#This Row],[Respuesta]]="","Sin respuesta","Respondido") -> Respondido
A34: 451 | B34: 34 | C34: Fleischmann S. A. | E34: GENERAL/ADM | F34: Según lo indicado en el RFP INSTALCIONES EX05_REV2 se solicita indicar si los TAG son solo en español. | G34: 4.6 TAG – Identificación de los equipos | H34: Si, solo en español | J34: =IF(Tabla1[[#This Row],[Respuesta]]="","Sin respuesta","Respondido") -> Respondido
A35: 450 | B35: 33 | C35: Fleischmann S. A. | E35: GENERAL/ADM | F35: Según lo indicado en el RFP INSTALCIONES EX05_REV2, De acuerdo a la respuesta N°63,64,65,66,68 .Se solicita aclarar que partidas requieren Ensayos de hormigón y acero estructural, Ensayos de compactación de suelos, Áreas sometidas a procesos de impermeabilización, en vista que las respuesta anteriores indican que esto no es parte del alcance y que está ejecutado. | G35: 4.5 Control de calidad – Materiales y servicios | H35: De acuerdo a lo especificado y normativa nacional vigente para las partidas que se ejecutaran. | J35: =IF(Tabla1[[#This Row],[Respuesta]]="","Sin respuesta","Respondido") -> Respondido
A36: 449 | B36: 32 | C36: Fleischmann S. A. | E36: GENERAL/ADM | F36: Se solicita aclaración para dar cumplimiento al pto 4.3.8 RFP INSTALCIONES EX05_REV2 , el hito indicado en el Anexo III "Entrega final de ingeniería de suportaciones" es de responsabilidad del proponente? , en caso de ser afirmativo, se requiere fecha de entrega de PLANOS y MODELO BIM IFC coordinado con la parrilla existente (alturas y ubicación) ya que hay instalaciones que chocan con vigas estructurales en el modelo entregado. | G36: ANEXO III_Programa de Construcción ST01 Fase 5-E2_revA, RFP INSTALCIONES EX05_REV2 | H36: Es responsabilidad del Proponente, ver respuestas 23, 140, 236 y 241 . Ver numerales 4.3.8, 5.4 y 5.5 del RFP | J36: =IF(Tabla1[[#This Row],[Respuesta]]="","Sin respuesta","Respondido") -> Respondido
A37: 448 | B37: 31 | C37: Fleischmann S. A. | E37: OOCC | F37: Se solicita enviar memorias de cálculo de la parrilla metálica destinada a la suspensión de cielos e instalaciones, incluyendo la capacidad portante y límites de carga admisibles del sistema., que contenga Esquemas y planos de la parrilla metálica. criterios de diseño y normas de referencia utilizadas, cálculos de capacidad de carga y factores de seguridad considerados, recomendaciones para la configuración de la Soportación en función de los pesos previstos. | G37: 4.3.8 Ingeniería y Suministro de Sistemas de Soportación de especialidades. | H37: Se adjunta. | J37: =IF(Tabla1[[#This Row],[Respuesta]]="","Sin respuesta","Respondido") -> Respondido
A38: 447 | B38: 30 | C38: Fleischmann S. A. | E38: GENERAL/ADM | F38: Indicar si la Carta Gantt recibida como antecedente tiene días corridos o hábiles, además el calendario no contienen feriados. | H38: Debe ser utilizada para entender los plazos generales, la programación de la obra y la configuración de días trabajados feriados etc., es de exclusiva responsabilidad del proponente. | J38: =IF(Tabla1[[#This Row],[Respuesta]]="","Sin respuesta","Respondido") -> Respondido
A39: 446 | B39: 29 | C39: Fleischmann S. A. | E39: BMS | F39: La canalización de Fibra Óptica (Fiber Runner) se deberá considerar en esta etapa junto con las bajadas a cada Rack? | H39: No | J39: =IF(Tabla1[[#This Row],[Respuesta]]="","Sin respuesta","Respondido") -> Respondido
A40: 445 | B40: 28 | C40: Fleischmann S. A. | E40: BMS | F40: Estación de Monitoreo (Onyxworks) Se deberá considerar para esta etapa o es existente en etapas anteriores? | H40: Se debe considerar | J40: =IF(Tabla1[[#This Row],[Respuesta]]="","Sin respuesta","Respondido") -> Respondido
A41: 444 | B41: 27 | C41: Fleischmann S. A. | E41: ELECTRICO | F41: Se solicita mode y marca de los sensores de movimiento, o equivalente técnico. | H41: El proveedor adjudicado deberá presentar la propuesta para este elemeto y esta deberá ser validada por Odata | J41: =IF(Tabla1[[#This Row],[Respuesta]]="","Sin respuesta","Respondido") -> Respondido
...
